Workbook

Sheet Инвойс
C1: ИНВОЙС № AGB-101 от | F1: 31.08.2025г.
C2: к контракту № АG/B-2/0725 от 25.07.2025 года
A4: Продавец: | G4: Покупатель:
A5: ООО “AAZZ GROUP” | G5: ООО «БЕНУА»
A6: Респyблика Узбекистан, Хорезмская область, | G6: 199004, г. Санкт-Петербург, наб. Макарова, д. 14,
A7: Ургенчский р-н, Мевазор МФИ, улица Мустакиллик, д.6/2 | G7: литера А, пом. 1-Н, рабочее место 11.
A8: Р/с 20208840707099612003 (USD) | G8: ОГРН 1247800053544 / ИНН: 7801734052 / 780101001
A9: Банк: АКБ «Гарант Банк » | G9: Банк: Азия-Инвест Банк (АО) Свифт: ASIJRUMM
A10: МФО: 00439; SWIFTCode: JSCSUZ22 | G10: Счет получателя (RUB)№ 40702810302100012537
A11: ИНН: 311440436 | G11: К/С 21002840900090007001 Банк-корреспондент: УЗНАЦБАНК
A13: Грузоотправитель: | G13: Грузополучатель:
A14: ООО “AAZZ GROUP” | G14: OOO «Сармант-ЮГ»
A15: Респyблика Узбекистан, Хорезмская область, | G15: 196006, город Санкт-Петербург, улица Новорощинская,
A16: Ургенчский р-н, Мевазор МФИ, улица Мустакиллик, д.6/2 | G16: дом 4, литер А, 1Н помещение 363 офис 609-1
... A20: ИНН: 311440436 | G20: ИНН/КПП 7805640197/ 781001001 ОГРН 1147847003193
A22: Координаты | C22: ГЛОНАСС 41.3805768, 69.3187795
A23: Место там.очиски: | C23: Московская областная таможня Новомосковский Т/П (код поста 10132180) 142770 Москва, поселение Сосенское, дер. Николо-Хованское, СТР. 2004 СВХ ООО «ФУД ЛОГИСТИКС»
A24: Условия поставки: | C24: DAP - с Атамакен, Республика Казахстан
A25: Страна происхождения товара: | C25: Республика Узбекистан
A26: Вид транспорта и номер : | C26: Автотранспорт № | E26: 90135JBA/902422BA
A27: Урожай 2025 года
A28: № | B28: Наименование товаров (работ, услуг) | C28: Код ТН ВЭД | D28: Вид Упак | E28: мест | F28: Ед. изм. | G28: Кол-во товара | I28: Цена за ед. изм | J28: Стоимость поставки | K28: НДС | M28: Стоимость поставки с учетом НДС (доллар США)
G29: брутто | H29: нетто | J29: (нетто) тн. | K29: ставка | L29: сумма
A30: 1 | B30: Виноград свежий столовых сортов | C30: 0806101001 | D30: Пласт. ящик | E30: 2300 | F30: кг | G30: 22710 | H30: 21100 | I30: 0.95 | J30: =H30*I30 -> 20045 | K30: 0 | L30: 0 | M30: =J30 -> 20045
A31: ИТОГО: | E31: =SUM(E30:E30) -> 2300 | G31: =SUM(G30:G30) -> 22710 | H31: =SUM(H30:H30) -> 21100 | J31: =SUM(J30:J30) -> 20045 | M31: =SUM(M30:M30) -> 20045
A32: Сумма прописью: | E32: =Лист1!B3 -> Двадцать тысяч сорок пять долларов США, 00 центов.
A35: Примечание: Товар уложен на деревянные палеты с дерев.рейками, которые не являются товаром и предназначенны для устойчивости и циркуляции охлаждающего воздуха. Вес паллет и дер.реек: 400 кг.
A37: Руководитель Поставщика_________________ | D37: Курбаниезов А.А.
A39: М.П.
A41: Товар отпустил

Sheet CMR
B2: =+Инвойс!A5 -> ООО “AAZZ GROUP”
B3: =+Инвойс!A6 -> Респyблика Узбекистан, Хорезмская область,
B4: =+Инвойс!A7 -> Ургенчский р-н, Мевазор МФИ, улица Мустакиллик, д.6/2
B7: =+Инвойс!G14 -> OOO «Сармант-ЮГ»
B8: =+Инвойс!G15 -> 196006, город Санкт-Петербург, улица Новорощинская,
B9: =+Инвойс!G16 -> дом 4, литер А, 1Н помещение 363 офис 609-1
B10: по поручению | C10: =+Инвойс!G5 -> ООО «БЕНУА»
B13: г.Оренбург/г.Казань/г.Москва/г.Санкт-Петербург/г.Пермь/г. Новосибирск /г.Красноярск/г.Челябинск/г.Екатеринбург/
A14: Российская Федерация | B14: /г. Владивосток/ г.Чита / г. Пенза / г. Краснодар / г.Пятигорск / г.Воронеж / /г.Нижневартовск/г.Нижний Новгород/г.Киров
B16: г.Самара/ г.Уфа / /г. Иркутск /г.Омск /г. Ижевск/ Российская федерация
B18: Узбекистан Ташкент
C22: =+Инвойс!F1 -> 31.08.2025г.
B24: =+CONCATENATE(Инвойс!C1,Инвойс!F1) -> ИНВОЙС № AGB-101 от 31.08.2025г.
B25: ТИР № XK87039375
B30: =+Инвойс!A30 -> 1 | C30: =+Инвойс!E30 -> 2300 | D30: =+Инвойс!D30 -> Пласт. ящик | F30: =+Инвойс!B30 -> Виноград свежий столовых сортов | G30: =+Инвойс!C30 -> 0806101001 | I30: =+Инвойс!G30 -> 22710
B45: =+Инвойс!C23 -> Московская областная таможня Новомосковский Т/П (код поста 10132180) 142770 Москва, поселение Сосенское, дер. Николо-Хованское, СТР. 2004 СВХ ООО «ФУД ЛОГИСТИКС»
B49: Ташкент | D49: =+C22 -> 31.08.2025г.
A57: а/м-п/п гос № | C57: =+Инвойс!E26 -> 90135JBA/902422BA

Sheet TIR
B2: Узбекистан
D7: Узбекистан | G7: Россия
B14: =+Инвойс!E26 -> 90135JBA/902422BA | H14: CMR № б/н от | J14: =+Инвойс!F1 -> 31.08.2025г.
G15: ИНВ № T-44 от 12.06.2018г. | H15: =+CMR!B24 -> ИНВОЙС № AGB-101 от 31.08.2025г.
F18: =+Инвойс!E30 -> 2300 | G18: =+CMR!F30 -> Виноград свежий столовых сортов
F19: =+Инвойс!D30 -> Пласт. ящик | G19: =+Инвойс!C30 -> 0806101001 | I19: Брутто | J19: =+Инвойс!G30 -> 22710
D47: =+F18+F20+F22+F24+F26+F28+F30+F32+F34+F36+F38+F40+F42 -> 2300
B48: РОССИЯ

Sheet SPETS
B1: Спецификация № AGB-101 от | F1: =+Инвойс!F1 -> 31.08.2025г.
C2: =+Инвойс!C2 -> к контракту № АG/B-2/0725 от 25.07.2025 года
A4: Продавец: | G4: Покупатель:
A5: =+Инвойс!A5 -> ООО “AAZZ GROUP” | G5: =+Инвойс!G5 -> ООО «БЕНУА»
A6: =+Инвойс!A6 -> Респyблика Узбекистан, Хорезмская область, | G6: =+Инвойс!G6 -> 199004, г. Санкт-Петербург, наб. Макарова, д. 14,
A7: =+Инвойс!A7 -> Ургенчский р-н, Мевазор МФИ, улица Мустакиллик, д.6/2 | G7: =+Инвойс!G7 -> литера А, пом. 1-Н, рабочее место 11.
A8: =+Инвойс!A8 -> Р/с 20208840707099612003 (USD) | G8: =+Инвойс!G8 -> ОГРН 1247800053544 / ИНН: 7801734052 / 780101001
A9: =+Инвойс!A9 -> Банк: АКБ «Гарант Банк » | G9: =+Инвойс!G9 -> Банк: Азия-Инвест Банк (АО) Свифт: ASIJRUMM
A10: =+Инвойс!A10 -> МФО: 00439; SWIFTCode: JSCSUZ22 | G10: =+Инвойс!G10 -> Счет получателя (RUB)№ 40702810302100012537
A11: =+Инвойс!A11 -> ИНН: 311440436 | G11: =+Инвойс!G11 -> К/С 21002840900090007001 Банк-корреспондент: УЗНАЦБАНК
A13: Грузоотправитель: | G13: Грузополучатель:
A14: =+Инвойс!A14 -> ООО “AAZZ GROUP” | G14: =+Инвойс!G14 -> OOO «Сармант-ЮГ»
A15: =+Инвойс!A15 -> Респyблика Узбекистан, Хорезмская область, | G15: =+Инвойс!G15 -> 196006, город Санкт-Петербург, улица Новорощинская,
A16: =+Инвойс!A16 -> Ургенчский р-н, Мевазор МФИ, улица Мустакиллик, д.6/2 | G16: =+Инвойс!G16 -> дом 4, литер А, 1Н помещение 363 офис 609-1
A17: =+Инвойс!A17 -> Р/с 20208840707099612003 (USD) | G17: =+Инвойс!G17 -> р/с USD 40702810226710000073
A18: =+Инвойс!A18 -> Банк: АКБ «Гарант Банк » | G18: =+Инвойс!G18 -> Банк: Филиал «Центральный» Банка ВТБ (ПАО) в г. Москве
A19: =+Инвойс!A19 -> МФО: 00439; SWIFTCode: JSCSUZ22 | G19: =+Инвойс!G19 -> SWIFT: VTBRRUM2MS2
A20: =+Инвойс!A20 -> ИНН: 311440436 | G20: =+Инвойс!G20 -> ИНН/КПП 7805640197/ 781001001 ОГРН 1147847003193
A22: Координаты | C22: ГЛОНАСС 41.3805768, 69.3187795
A23: Место там.очиски: | C23: в течение 180 дней после завершения таможенного оформления в Российской Федерации
A24: Условия поставки: | C24: =+Инвойс!C24 -> DAP - с Атамакен, Республика Казахстан
A25: Страна происхождения товара: | C25: Республика Узбекистан
A26: Вид транспорта и номер : | C26: Автотранспорт № | E26: =+Инвойс!E26 -> 90135JBA/902422BA
A27: Урожай 2025 года
A28: № | B28: Наименование товаров (работ, услуг) | C28: Код ТН ВЭД | D28: Вид Упак | E28: мест | F28: Ед. изм. | G28: Кол-во товара | I28: Цена за ед. изм | J28: Стоимость поставки | K28: НДС | M28: Стоимость поставки с учетом НДС (доллар США)
G29: брутто | H29: нетто | J29: (нетто) тн. | K29: ставка | L29: сумма
A30: =+Инвойс!A30 -> 1 | B30: =+Инвойс!B30 -> Виноград свежий столовых сортов | C30: =+Инвойс!C30 -> 0806101001 | D30: =+Инвойс!D30 -> Пласт. ящик | E30: =+Инвойс!E30 -> 2300 | F30: =+Инвойс!F30 -> кг | G30: =+Инвойс!G30 -> 22710 | H30: =+Инвойс!H30 -> 21100 | ... M30: =+Инвойс!M30 -> 20045
A31: ИТОГО: | E31: =SUM(E30:E30) -> 2300 | G31: =+Инвойс!G31 -> 22710 | H31: =+Инвойс!H31 -> 21100 | J31: =+Инвойс!J31 -> 20045 | M31: =+Инвойс!M31 -> 20045
A32: Сумма прописью: | E32: =Лист1!B3 -> Двадцать тысяч сорок пять долларов США, 00 центов.
A36: Продавец | D36: Курбаниезов А.А. | G36: Покупатель | L36: Дуденков П.А.
A37: =+Инвойс!A5 -> ООО “AAZZ GROUP” | G37: =+Инвойс!G5 -> ООО «БЕНУА»
G50: =+Инвойс!G13 -> Грузополучатель: | L50: Исаков И.Н.
G51: =+Инвойс!G14 -> OOO «Сармант-ЮГ»

Sheet Лист2
A1: Код там. Поста 10412160 Оренбургская таможня т/п Соль-Илецкий, адрес 461504 г.Соль-Илецк, ул. Украинская, д.2
A3: Московская областная таможня Новомосковский Т/П (код поста 10132180) 142770 Москва, поселение Сосенское, дер. Николо-Хованское, СТР. 2004 СВХ ООО «ФУД ЛОГИСТИКС» | M3: DAP - с Казыгурт , Республика Казахстан | R3: MAYSKIY
A5: Челябинский таможенный пост г.Челябинск, ул.Игуменка 7 А, (код поста 10504080) | M5: DAP - с Атамакен, Республика Казахстан | R5: ILICH
A7: 10309200, Т/П ПРИКУБАНСКИЙ, Г.КРАСНОДАР СВХ ООО "КОНСАЛТТАМОЖСЕРВИС" 350072, РФ, Г.КРАСНОДАР, УЛ.ТОПОЛИНАЯ, 4 Свидетельство СВХ № 10309/070721/10150/3 | M7: DAP - с Жибек Жолы , Республика Казахстан | R7: YALLAMA
A9: г.Новосибирск, ч/з Новосибирский з/т пост, г.Новосибирск, ул.Толмачевская, д.1/1. код поста 10609030 | M9: DAP - с Акжигит , Республика Казахстан | R9: DOUT-OTA
A11: СВХ ООО "ОМАС" (код поста 10610050) 644117, Омская обл., г. Омск, ул. 3-я Молодежная, № лицензии: 10610/150515/10055/2
A13: т/п "Астраханский" Код поста 10311020, 414042, г. Астрахань, Трусовский р-н. ул. Мосина, д. 1Аlic. 10013/200111/10112/12 dđ 09/02/2021
A15: т/п Тольяттинский код поста 10412110 4450043 Самарская обл. г.Тольятти Автозаводский р-н. ул. Вокзальная д.2 СВХ «ГРИНЛАЙН»
A17: Октябрский таможенный пост, код поста 10502090, АО СИАЙТИ ТЕРМИНАЛ 620025, Свердловкая обл. г.Екатеринбург, ул.Бахчиванджи, д.2. Российская Федерация.
A19: Красноярский таможенный пост. Код поста 10606060. Адрес поста Российская Федерация г.Красноярск, ул.Ястынская 47в, строение 12. СВХ «Агротерминал-Таможня»

Sheet Лист1
A1: В ячейке Е2 должна быть ссылка на исходное число
E2: =Инвойс!M31 -> 20045 | G2: 357.79119
A3: Заглавная без НДС | B3: =SUBSTITUTE(B5,F9,F10,1) -> Двадцать тысяч сорок пять долларов США, 00 центов. | M3: Сегодня с утра судя по всему было | N3: =TODAY() -> 45900 | P3: =DAY(N3) -> 31 | Q3: =IF(Q4>7,S3,S4) -> августа | R3: =YEAR(N3) -> 2025 | S3: =IF(Q4=8,"августа",IF(Q4=9,"сентября",IF(Q4=10,"октября",IF(Q4=11,"ноября",IF(Q4=12,"декабря","не отсюда"))))) -> августа
A4: Заглавная с НДС | B4: =SUBSTITUTE(B6,F9,F10,1) -> Двадцать тысяч сорок пять долларов США, 00 центов. (в т.ч. НДС - 357,79) | K4: =CONCATENATE(" « ",P3," » ",Q3," ",R3," г.") -> « 31 » августа 2025 г. | Q4: =MONTH(N3) -> 8 | S4: =IF(Q4=1,"января",IF(Q4=2,"февраля",IF(Q4=3,"марта",IF(Q4=4,"апреля",IF(Q4=5,"мая",IF(Q4=6,"июня",IF(Q4=7,"июля","брать не отсюда"))))))) -> брать не отсюда
A5: маленькая без НДС | B5: =CONCATENATE(A8,A9,A10,A11,A12) -> двадцать тысяч сорок пять долларов США, 00 центов.
A6: маленькая с НДС | B6: =CONCATENATE(A8,A9,A10,A11,A12,B8,B9,C9) -> двадцать тысяч сорок пять долларов США, 00 центов. (в т.ч. НДС - 357,79)
H7: Для справки - смотрите примечания к ячейкам E4 B8 B9 этого листа и H2 и C34 предыдущего.
A8: =CONCATENATE(IF(B15=0,"",E15),IF(B16=0,"",IF(C17<20,IF(C17<16,IF(C17<10,E16,D17),F17),E16)),IF(B17=0,"",IF(NOT(B16=1),E17,"")),F18) | B8: (в т.ч. НДС - | F8: =CODE(B6) -> 228
A9: =CONCATENATE(IF(B19=0,"",E19),IF(B20=0,"",IF(C21<20,IF(C21<16,IF(C21<10,E20,D21),F21),E20)),IF(B21=0,"",IF(NOT(B20=1),E21,"")),F22) | B9: =ROUND((G2),2) -> 357.79 | C9: ) | F9: =CHAR(F8) -> д
A10: =CONCATENATE(IF(B23=0,"",E23),IF(B24=0,"",IF(C25<20,IF(C25<16,IF(C25<10,E24,D25),F25),E24)),IF(B25=0,"",IF(NOT(B24=1),E25,"")),F26) -> двадцать тысяч | F10: =PROPER(F9) -> Д
A11: =CONCATENATE(IF(B27=0,"",E27),IF(B28=0,"",IF(C29<20,IF(C29<16,IF(C29<10,E28,D29),F29),E28)),IF(B29=0,"",IF(NOT(B28=1),E29,"")),F30) -> сорок пять долларов США,
A12: =CONCATENATE(IF(C31=0,"0",C31),IF(C32=0,"0",C32)," ",F33) -> 00 центов. | M12: =TODAY() -> 45900
E13: =TRUNC(E2) -> 20045 | F13: рублей
A14: =TRUNC(A15/10) -> 0
A15: =TRUNC(A16/10) -> 0 | B15: =TRUNC(RIGHT(A15)) -> 0 | C15: =B15 -> 0 | E15: =IF(B15=1,E43,IF(B15=2,G35,IF(B15=3,G36,IF(B15=4,G37,IF(B15=5,G38,IF(B15=6,G39,IF(B15=7,G40,IF(B15=8,G41,G42)))))))) -> девятьсот
A16: =TRUNC(A17/10) -> 0 | B16: =TRUNC(RIGHT(A16)) -> 0 | C16: =IF(B16=1,"",B16) -> 0 | E16: =IF(OR(C16=0,B16=1),"",IF(B16=2,E35,IF(B16=3,E36,IF(B16=4,E37,IF(B16=5,E38,IF(B16=6,E39,IF(B16=7,E40,IF(B16=8,E41,E42))))))))
A17: =TRUNC(A19/10) -> 0 | B17: =TRUNC(RIGHT(A17)) -> 0 | C17: =IF(B16=1,B17+10,IF(B17=0,0,B17)) -> 0 | D17: =IF(AND(C17>9,C17<16),IF(C17=10,D34,IF(C17=11,D35,IF(C17=12,D36,IF(C17=13,D37,IF(C17=14,D38,IF(C17=15,D39,)))))),"") | E17: =IF(B17=1,A34,IF(B17=2,A35,IF(B17=3,A36,IF(B17=4,A37,IF(B17=5,A38,IF(B17=6,A39,IF(B17=7,A40,IF(B17=8,A41,A42)))))))) -> девять | F17: =IF(AND(C17>15,C17<20),IF(C17=16,D40,IF(C17=17,D41,IF(C17=18,D42,IF(C17=19,D43,)))),"")
E18: =B17+B16*10+B15*100 -> 0 | F18: =IF(E18=0,"",IF(B16=1,"миллиардов ",IF(B17=1,"милиард ",IF(OR(B17=2,B17=3,B17=4),"миллиарда ","милиардов "))))
A19: =TRUNC(A20/10) -> 0 | B19: =TRUNC(RIGHT(A19)) -> 0 | C19: =B19 -> 0 | E19: =IF(B19=1,E43,IF(B19=2,G35,IF(B19=3,G36,IF(B19=4,G37,IF(B19=5,G38,IF(B19=6,G39,IF(B19=7,G40,IF(B19=8,G41,G42)))))))) -> девятьсот
A20: =TRUNC(A21/10) -> 0 | B20: =TRUNC(RIGHT(A20)) -> 0 | C20: =IF(B20=1,"",B20) -> 0 | E20: =IF(OR(C20=0,B20=1),"",IF(B20=2,E35,IF(B20=3,E36,IF(B20=4,E37,IF(B20=5,E38,IF(B20=6,E39,IF(B20=7,E40,IF(B20=8,E41,E42))))))))
A21: =TRUNC(A23/10) -> 0 | B21: =TRUNC(RIGHT(A21)) -> 0 | C21: =IF(B20=1,B21+10,IF(B21=0,0,B21)) -> 0 | D21: =IF(AND(C21>9,C21<16),IF(C21=10,D34,IF(C21=11,D35,IF(C21=12,D36,IF(C21=13,D37,IF(C21=14,D38,IF(C21=15,D39,)))))),"") | E21: =IF(B21=1,A34,IF(B21=2,A35,IF(B21=3,A36,IF(B21=4,A37,IF(B21=5,A38,IF(B21=6,A39,IF(B21=7,A40,IF(B21=8,A41,A42)))))))) -> девять | F21: =IF(AND(C21>15,C21<20),IF(C21=16,D40,IF(C21=17,D41,IF(C21=18,D42,IF(C21=19,D43,)))),"")
E22: =B21+B20*10+B19*100 -> 0 | F22: =IF(E22=0,"",IF(B20=1,"миллионов ",IF(B21=1,"миллион ",IF(OR(B21=2,B21=3,B21=4),"миллиона ","миллионов "))))
A23: =TRUNC(A24/10) -> 0 | B23: =TRUNC(RIGHT(A23)) -> 0 | C23: =B23 -> 0 | E23: =IF(B23=1,E43,IF(B23=2,G35,IF(B23=3,G36,IF(B23=4,G37,IF(B23=5,G38,IF(B23=6,G39,IF(B23=7,G40,IF(B23=8,G41,G42)))))))) -> девятьсот
A24: =TRUNC(A25/10) -> 2 | B24: =TRUNC(RIGHT(A24)) -> 2 | C24: =IF(B24=1,"",B24) -> 2 | E24: =IF(OR(C24=0,B24=1),"",IF(B24=2,E35,IF(B24=3,E36,IF(B24=4,E37,IF(B24=5,E38,IF(B24=6,E39,IF(B24=7,E40,IF(B24=8,E41,E42)))))))) -> двадцать
A25: =TRUNC(A27/10) -> 20 | B25: =TRUNC(RIGHT(A25)) -> 0 | C25: =IF(B24=1,B25+10,IF(B25=0,0,B25)) -> 0 | D25: =IF(AND(C25>9,C25<16),IF(C25=10,D34,IF(C25=11,D35,IF(C25=12,D36,IF(C25=13,D37,IF(C25=14,D38,IF(C25=15,D39,)))))),"") | E25: =IF(B25=1,B34,IF(B25=2,B35,IF(B25=3,A36,IF(B25=4,A37,IF(B25=5,A38,IF(B25=6,A39,IF(B25=7,A40,IF(B25=8,A41,A42)))))))) -> девять | F25: =IF(AND(C25>15,C25<20),IF(C25=16,D40,IF(C25=17,D41,IF(C25=18,D42,IF(C25=19,D43,)))),"")
E26: =B23*100+B24*10+B25 -> 20 | F26: =IF(E26=0,"",IF(B24=1,"тысяч ",IF(B25=1,"тысяча ",IF(OR(B25=2,B25=3,B25=4),"тысячи ","тысяч ")))) -> тысяч
A27: =TRUNC(A28/10) -> 200 | B27: =TRUNC(RIGHT(A27)) -> 0 | C27: =B27 -> 0 | E27: =IF(B27=1,E43,IF(B27=2,G35,IF(B27=3,G36,IF(B27=4,G37,IF(B27=5,G38,IF(B27=6,G39,IF(B27=7,G40,IF(B27=8,G41,G42)))))))) -> девятьсот
A28: =TRUNC(A29/10) -> 2004 | B28: =TRUNC(RIGHT(A28)) -> 4 | C28: =IF(B28=1,"",B28) -> 4 | E28: =IF(OR(C28=0,B28=1),"",IF(C28=2,E35,IF(C28=3,E36,IF(C28=4,E37,IF(C28=5,E38,IF(C28=6,E39,IF(C28=7,E40,IF(C28=8,E41,E42)))))))) -> сорок
A29: =E13 -> 20045 | B29: =TRUNC(RIGHT(A29)) -> 5 | C29: =IF(B28=1,B29+10,IF(B29=0,0,B29)) -> 5 | D29: =IF(AND(C29>9,C29<16),IF(C29=10,D34,IF(C29=11,D35,IF(C29=12,D36,IF(C29=13,D37,IF(C29=14,D38,IF(C29=15,D39,)))))),"") | E29: =IF(B29=1,A34,IF(B29=2,A35,IF(B29=3,A36,IF(B29=4,A37,IF(B29=5,A38,IF(B29=6,A39,IF(B29=7,A40,IF(B29=8,A41,A42)))))))) -> пять | F29: =IF(AND(C29>15,C29<20),IF(C29=16,D40,IF(C29=17,D41,IF(C29=18,D42,IF(C29=19,D43,)))),"")
E30: =B27*100+B28*10+B29 -> 45 | F30: =IF(E30+E26+E22+E18=0,"ноль долларов США,",IF(C29=1,"доллар США,",IF(OR(C29=2,C29=3,C29=4),"доллара США,","долларов США, "))) -> долларов США,
A31: =ROUND(100*(E2-E13),0) -> 0 | C31: =TRUNC(A31/10) -> 0 | E31: =IF(OR(C31=1,C31=0),"",IF(C31=2,E35,IF(C31=3,E36,IF(C31=4,E37,IF(C31=5,E38,IF(C31=6,E39,IF(C31=7,E40,IF(C31=8,E41,E42))))))))
C32: =TRUNC(A31-C31*10) -> 0 | E32: =IF(C32=1,B34,IF(C32=2,B35,IF(C32=3,A36,IF(C32=4,A37,IF(C32=5,A38,IF(C32=6,A39,IF(C32=7,A40,IF(C32=8,A41,A42)))))))) -> девять
F33: центов.
A34: один | B34: одна | D34: десять
A35: два | B35: две | D35: одиннадцать | E35: двадцать | G35: двести
A36: три | D36: двенадцать | E36: тридцать | G36: триста
A37: четыре | D37: тринадцать | E37: сорок | G37: четыреста
A38: пять | D38: четырнадцать | E38: пятьдесят | G38: пятьсот
A39: шесть | D39: пятнадцать | E39: шестьдесят | G39: шестьсот
A40: семь | D40: шестнадцать | E40: семьдесят | G40: семьсот
...
