Workbook

Sheet Инвойс
C1: ИНВОЙС № M-227 от | F1: 27.08.2025г.
C2: к контракту № FM-5 от 25.06.2025г года
A4: Продавец: | G4: Покупатель:
A5: LLC «Fresh Food Export NN» | G5: ООО "МЕГАТОРГ"
A6: Республика Узбекистан, Наманганская область, | G6: 108826, Город Москва, вн.тер. г.Поселение Сосенское, п Коммунарка,
A7: Наманганский район, Катта Тошбулок МФЙ, ул. Мустакиллик дом 86. | G7: ул. Потаповская Роща, дом 5, корпус 2, помещение 1/П
A8: Р/с N 20208840107243861001 (USD) ИНН: 312139894 | G8: Банк: АО "АЛЬФА-БАНК" ИНН / КПП: 7751302030 /775101001
A9: Банк: “Business Development Bank” JSCB, г.Ташкент МФО: 01037, | G9: Р/Счет: 40702810802010005175 ; БИК: 044525593
A10: Корресп. Банки: 1. “National Bank for Foreign Economic | G10: Корр.счет: 30101810200000000593 ОГРН:1247700169122
A11: Activity of the Republic of Uzbekistan”, SWIFT: NBFAUZ2X, | G11: Телефон: + 7 926 281-88-66
A12: к/с: 21002840300000452002 (USD) 2. JSC “ASIA INVEST BANK”, Moscow, Russia БИК: 044525234, КПП: 770501001, ИНН: 7724187003 SWIFT: ASIJRUMM, к/с: 30111810500000000061 (RUB)
A13: Грузоотправитель: | G13: Грузополучатель:
A14: LLC «Fresh Food Export NN» | G14: OOO «Сармант-ЮГ»
A15: Республика Узбекистан, Наманганская область, | G15: 196006, город Санкт-Петербург, улица Новорощинская,
A16: Наманганский район, Катта Тошбулок МФЙ, ул. Мустакиллик дом 86. | G16: дом 4, литер А, 1Н помещение 363 офис 609-1
A17: Р/с N 20208840107243861001 (USD) ИНН: 312139894 | G17: р/с USD 40702810226710000073
A18: Банк: “Business Development Bank” JSCB, г.Ташкент МФО: 01037, | G18: Банк: Филиал «Центральный» Банка ВТБ (ПАО) в г. Москве
A19: Корресп. Банки: 1. “National Bank for Foreign Economic | G19: SWIFT: VTBRRUM2MS2
A20: Activity of the Republic of Uzbekistan”, SWIFT: NBFAUZ2X, | G20: ИНН/КПП 7805640197/ 781001001 ОГРН 1147847003193
A21: к/с: 21002840300000452002 (USD) 2. JSC “ASIA INVEST BANK”, Moscow, Russia БИК: 044525234, КПП: 770501001, ИНН: 7724187003 SWIFT: ASIJRUMM, к/с: 30111810500000000061 (RUB)
A22: Координаты | C22: ГЛОНАСС 41.3805768, 69.3187795
A23: Место там.очиски: | C23: Московская областная таможня Новомосковский Т/П (код поста 10132180) 142770 Москва, поселение Сосенское, дер. Николо-Хованское, СТР. 2004 СВХ ООО «ФУД ЛОГИСТИКС»
A24: Условия поставки: | C24: DAP - г. Соль-Илецк, Российская Федерация (согласно Incoterms 2010)
A25: Страна происхождения товара: | C25: Республика Узбекистан
A26: Вид транспорта и номер : | C26: Автотранспорт № | E26: 40448WBA/405699BA
A27: Урожай 2025 года
A28: № | B28: Наименование товаров (работ, услуг) | C28: Код ТН ВЭД | D28: Вид Упак | E28: мест | F28: Ед. изм. | G28: Кол-во товара | I28: Цена за ед. изм | J28: Стоимость поставки | K28: НДС | M28: Стоимость поставки с учетом НДС (доллар США)
G29: брутто | H29: нетто | J29: (нетто) тн. | K29: ставка | L29: сумма
A30: 1 | B30: Виноград свежий столовых сортов | C30: 0806101001 | D30: Дер. ящик | E30: 1576 | F30: кг | G30: 14686 | H30: 12480 | I30: 1.05 | J30: =H30*I30 -> 13104 | K30: 0 | L30: 0 | M30: =J30 -> 13104
A31: 2 | B31: Сливы свежие | C31: 0809400501 | D31: Дер. ящик | E31: 218 | F31: кг | G31: 1965 | H31: 1660 | I31: 0.65 | J31: =H31*I31 -> 1079 | K31: 0 | L31: 0 | M31: =J31 -> 1079
A32: 3 | B32: Айва свежая | C32: 0808400009 | D32: Дер. ящик | E32: 150 | F32: кг | G32: 900 | H32: 690 | I32: 1.5 | J32: =H32*I32 -> 1035 | K32: 0 | L32: 0 | M32: =J32 -> 1035
A33: 4 | B33: Хурма свежая | C33: 0810700009 | D33: Дер. ящик | E33: 265 | F33: кг | G33: 2121 | H33: 1750 | I33: 3.1 | J33: =H33*I33 -> 5425 | K33: 0 | L33: 0 | M33: =J33 -> 5425
A34: 5 | B34: Гранат свежий | C34: 0810907504 | D34: Дер. ящик | E34: 380 | F34: кг | G34: 3042 | H34: =+G34-E34*1.4 -> 2510 | I34: 1.95 | J34: =H34*I34 -> 4894.5 | K34: 0 | L34: 0 | M34: =J34 -> 4894.5
A35: ИТОГО: | E35: =SUM(E30:E34) -> 2589 | G35: =SUM(G30:G34) -> 22714 | H35: =SUM(H30:H34) -> 19090 | J35: =SUM(J30:J34) -> 25537.5 | M35: =SUM(M30:M34) -> 25537.5
A36: Сумма прописью: | E36: =Лист1!B3 -> Двадцать пять тысяч пятьсот тридцать семь долларов США, 50 центов.
A38: Примечание: Товар уложен на деревянные палеты с дерев.рейками, которые не являются товаром и предназначенны для устойчивости и циркуляции охлаждающего воздуха. Вес паллет и дер.реек: 400 кг.
A40: Руководитель Поставщика_________________ | D40: Вахабов Ж.А.
A42: М.П.
A44: Товар отпустил

Sheet CMR
B2: =+Инвойс!A5 -> LLC «Fresh Food Export NN»
B3: =+Инвойс!A6 -> Республика Узбекистан, Наманганская область,
B4: =+Инвойс!A7 -> Наманганский район, Катта Тошбулок МФЙ, ул. Мустакиллик дом 86.
B7: =+Инвойс!G14 -> OOO «Сармант-ЮГ»
B8: =+Инвойс!G15 -> 196006, город Санкт-Петербург, улица Новорощинская,
B9: =+Инвойс!G16 -> дом 4, литер А, 1Н помещение 363 офис 609-1
B10: по поручению | C10: =+Инвойс!G5 -> ООО "МЕГАТОРГ"
B13: г.Оренбург/г.Казань/г.Москва/г.Санкт-Петербург/г.Пермь/г. Новосибирск /г.Красноярск/г.Челябинск/г.Екатеринбург/
A14: Российская Федерация | B14: /г. Владивосток/ г.Чита / г. Пенза / г. Краснодар / г.Пятигорск / г.Воронеж / /г.Нижневартовск/г.Нижний Новгород/г.Киров
B16: г.Самара/ г.Уфа / /г. Иркутск /г.Омск /г. Ижевск/ Российская федерация
B18: Узбекистан Сыр. обл.
C22: =+Инвойс!F1 -> 27.08.2025г.
B24: =+CONCATENATE(Инвойс!C1,Инвойс!F1) -> ИНВОЙС № M-227 от 27.08.2025г.
B25: ТИР № XK87039375
B30: =+Инвойс!A30 -> 1 | C30: =+Инвойс!E30 -> 1576 | D30: =+Инвойс!D30 -> Дер. ящик | F30: =+Инвойс!B30 -> Виноград свежий столовых сортов | G30: =+Инвойс!C30 -> 0806101001 | I30: =+Инвойс!G30 -> 14686
B31: =+Инвойс!A31 -> 2 | C31: =+Инвойс!E31 -> 218 | D31: =+Инвойс!D31 -> Дер. ящик | F31: =+Инвойс!B31 -> Сливы свежие | G31: =+Инвойс!C31 -> 0809400501 | I31: =+Инвойс!G31 -> 1965
B32: =+Инвойс!A32 -> 3 | C32: =+Инвойс!E32 -> 150 | D32: =+Инвойс!D32 -> Дер. ящик | F32: =+Инвойс!B32 -> Айва свежая | G32: =+Инвойс!C32 -> 0808400009 | I32: =+Инвойс!G32 -> 900
B33: =+Инвойс!A33 -> 4 | C33: =+Инвойс!E33 -> 265 | D33: =+Инвойс!D33 -> Дер. ящик | F33: =+Инвойс!B33 -> Хурма свежая | G33: =+Инвойс!C33 -> 0810700009 | I33: =+Инвойс!G33 -> 2121
B34: =+Инвойс!A34 -> 5 | C34: =+Инвойс!E34 -> 380 | D34: =+Инвойс!D34 -> Дер. ящик | F34: =+Инвойс!B34 -> Гранат свежий | G34: =+Инвойс!C34 -> 0810907504 | I34: =+Инвойс!G34 -> 3042
B45: =+Инвойс!C23 -> Московская областная таможня Новомосковский Т/П (код поста 10132180) 142770 Москва, поселение Сосенское, дер. Николо-Хованское, СТР. 2004 СВХ ООО «ФУД ЛОГИСТИКС»
B49: Сыр. обл | D49: =+C22 -> 27.08.2025г.
A57: а/м-п/п гос № | C57: =+Инвойс!E26 -> 40448WBA/405699BA

Sheet TIR
B2: Узбекистан
D7: Узбекистан | G7: Россия
B14: =+Инвойс!E26 -> 40448WBA/405699BA | H14: CMR № б/н от | J14: =+Инвойс!F1 -> 27.08.2025г.
G15: ИНВ № T-44 от 12.06.2018г. | H15: =+CMR!B24 -> ИНВОЙС № M-227 от 27.08.2025г.
F18: =+Инвойс!E30 -> 1576 | G18: =+CMR!F30 -> Виноград свежий столовых сортов
F19: =+Инвойс!D30 -> Дер. ящик | G19: =+Инвойс!C30 -> 0806101001 | I19: Брутто | J19: =+Инвойс!G30 -> 14686
F20: =+Инвойс!E31 -> 218 | G20: =+CMR!F31 -> Сливы свежие
F21: =+Инвойс!D31 -> Дер. ящик | G21: =+Инвойс!C31 -> 0809400501 | I21: Брутто | J21: =+Инвойс!G31 -> 1965
F22: =+Инвойс!E32 -> 150 | G22: =+CMR!F32 -> Айва свежая
F23: =+Инвойс!D32 -> Дер. ящик | G23: =+Инвойс!C32 -> 0808400009 | I23: Брутто | J23: =+Инвойс!G32 -> 900
F24: =+Инвойс!E33 -> 265 | G24: =+CMR!F33 -> Хурма свежая
F25: =+Инвойс!D33 -> Дер. ящик | G25: =+Инвойс!C33 -> 0810700009 | I25: Брутто | J25: =+Инвойс!G33 -> 2121
F26: =+Инвойс!E34 -> 380 | G26: =+CMR!F34 -> Гранат свежий
F27: =+Инвойс!D34 -> Дер. ящик | G27: =+Инвойс!C34 -> 0810907504 | I27: Брутто | J27: =+Инвойс!G34 -> 3042
D47: =+F18+F20+F22+F24+F26+F28+F30+F32+F34+F36+F38+F40+F42 -> 2589
B48: РОССИЯ

Sheet SPETS
B1: Спецификация № M-227 от | F1: =+Инвойс!F1 -> 27.08.2025г.
C2: =+Инвойс!C2 -> к контракту № FM-5 от 25.06.2025г года
A4: Продавец: | G4: Покупатель:
A5: =+Инвойс!A5 -> LLC «Fresh Food Export NN» | G5: =+Инвойс!G5 -> ООО "МЕГАТОРГ"
A6: =+Инвойс!A6 -> Республика Узбекистан, Наманганская область, | G6: =+Инвойс!G6 -> 108826, Город Москва, вн.тер. г.Поселение Сосенское, п Коммунарка,
A7: =+Инвойс!A7 -> Наманганский район, Катта Тошбулок МФЙ, ул. Мустакиллик дом 86. | G7: =+Инвойс!G7 -> ул. Потаповская Роща, дом 5, корпус 2, помещение 1/П
A8: =+Инвойс!A8 -> Р/с N 20208840107243861001 (USD) ИНН: 312139894 | G8: =+Инвойс!G8 -> Банк: АО "АЛЬФА-БАНК" ИНН / КПП: 7751302030 /775101001
A9: =+Инвойс!A9 -> Банк: “Business Development Bank” JSCB, г.Ташкент МФО: 01037, | G9: =+Инвойс!G9 -> Р/Счет: 40702810802010005175 ; БИК: 044525593
A10: =+Инвойс!A10 -> Корресп. Банки: 1. “National Bank for Foreign Economic | G10: =+Инвойс!G10 -> Корр.счет: 30101810200000000593 ОГРН:1247700169122
A11: =+Инвойс!A11 -> Activity of the Republic of Uzbekistan”, SWIFT: NBFAUZ2X, | G11: =+Инвойс!G11 -> Телефон: + 7 926 281-88-66
A12: =+Инвойс!A12 -> к/с: 21002840300000452002 (USD) 2. JSC “ASIA INVEST BANK”, Moscow, Russia БИК: 044525234, КПП: 770501001, ИНН: 7724187003 SWIFT: ASIJRUMM, к/с: 30111810500000000061 (RUB)
A13: Грузоотправитель: | G13: Грузополучатель:
A14: =+Инвойс!A14 -> LLC «Fresh Food Export NN» | G14: =+Инвойс!G14 -> OOO «Сармант-ЮГ»
A15: =+Инвойс!A15 -> Республика Узбекистан, Наманганская область, | G15: =+Инвойс!G15 -> 196006, город Санкт-Петербург, улица Новорощинская,
A16: =+Инвойс!A16 -> Наманганский район, Катта Тошбулок МФЙ, ул. Мустакиллик дом 86. | G16: =+Инвойс!G16 -> дом 4, литер А, 1Н помещение 363 офис 609-1
A17: =+Инвойс!A17 -> Р/с N 20208840107243861001 (USD) ИНН: 312139894 | G17: =+Инвойс!G17 -> р/с USD 40702810226710000073
A18: =+Инвойс!A18 -> Банк: “Business Development Bank” JSCB, г.Ташкент МФО: 01037, | G18: =+Инвойс!G18 -> Банк: Филиал «Центральный» Банка ВТБ (ПАО) в г. Москве
A19: =+Инвойс!A19 -> Корресп. Банки: 1. “National Bank for Foreign Economic | G19: =+Инвойс!G19 -> SWIFT: VTBRRUM2MS2
A20: =+Инвойс!A20 -> Activity of the Republic of Uzbekistan”, SWIFT: NBFAUZ2X, | G20: =+Инвойс!G20 -> ИНН/КПП 7805640197/ 781001001 ОГРН 1147847003193
A21: =+Инвойс!A21 -> к/с: 21002840300000452002 (USD) 2. JSC “ASIA INVEST BANK”, Moscow, Russia БИК: 044525234, КПП: 770501001, ИНН: 7724187003 SWIFT: ASIJRUMM, к/с: 30111810500000000061 (RUB)
A22: Координаты | C22: ГЛОНАСС 41.3805768, 69.3187795
A23: Условия оплаты: | C23: в течение 180 дней после завершения таможенного оформления в Российской Федерации
A24: Условия поставки: | C24: =+Инвойс!C24 -> DAP - г. Соль-Илецк, Российская Федерация (согласно Incoterms 2010)
A25: Страна происхождения товара: | C25: Республика Узбекистан
A26: Вид транспорта и номер : | C26: Автотранспорт № | E26: =+Инвойс!E26 -> 40448WBA/405699BA
A27: Урожай 2025 года
A28: № | B28: Наименование товаров (работ, услуг) | C28: Код ТН ВЭД | D28: Вид Упак | E28: мест | F28: Ед. изм. | G28: Кол-во товара | I28: Цена за ед. изм | J28: Стоимость поставки | K28: НДС | M28: Стоимость поставки с учетом НДС (доллар США)
G29: брутто | H29: нетто | J29: (нетто) тн. | K29: ставка | L29: сумма
A30: =+Инвойс!A30 -> 1 | B30: =+Инвойс!B30 -> Виноград свежий столовых сортов | C30: =+Инвойс!C30 -> 0806101001 | D30: =+Инвойс!D30 -> Дер. ящик | E30: =+Инвойс!E30 -> 1576 | F30: кг | G30: =+Инвойс!G30 -> 14686 | H30: =+Инвойс!H30 -> 12480 | I30: =+Инвойс!I30 -> 1.05 | J30: =+Инвойс!J30 -> 13104 | K30: 0 | L30: 0 | M30: =+Инвойс!M30 -> 13104
A31: =+Инвойс!A31 -> 2 | B31: =+Инвойс!B31 -> Сливы свежие | C31: =+Инвойс!C31 -> 0809400501 | D31: =+Инвойс!D31 -> Дер. ящик | E31: =+Инвойс!E31 -> 218 | F31: кг | G31: =+Инвойс!G31 -> 1965 | H31: =+Инвойс!H31 -> 1660 | I31: =+Инвойс!I31 -> 0.65 | J31: =+Инвойс!J31 -> 1079 | K31: 0 | L31: 0 | M31: =+Инвойс!M31 -> 1079
A32: =+Инвойс!A32 -> 3 | B32: =+Инвойс!B32 -> Айва свежая | C32: =+Инвойс!C32 -> 0808400009 | D32: =+Инвойс!D32 -> Дер. ящик | E32: =+Инвойс!E32 -> 150 | F32: кг | G32: =+Инвойс!G32 -> 900 | H32: =+Инвойс!H32 -> 690 | I32: =+Инвойс!I32 -> 1.5 | J32: =+Инвойс!J32 -> 1035 | K32: 0 | L32: 0 | M32: =+Инвойс!M32 -> 1035
A33: =+Инвойс!A33 -> 4 | B33: =+Инвойс!B33 -> Хурма свежая | C33: =+Инвойс!C33 -> 0810700009 | D33: =+Инвойс!D33 -> Дер. ящик | E33: =+Инвойс!E33 -> 265 | F33: кг | G33: =+Инвойс!G33 -> 2121 | H33: =+Инвойс!H33 -> 1750 | I33: =+Инвойс!I33 -> 3.1 | J33: =+Инвойс!J33 -> 5425 | K33: 0 | L33: 0 | M33: =+Инвойс!M33 -> 5425
A34: =+Инвойс!A34 -> 5 | B34: =+Инвойс!B34 -> Гранат свежий | C34: =+Инвойс!C34 -> 0810907504 | D34: =+Инвойс!D34 -> Дер. ящик | E34: =+Инвойс!E34 -> 380 | F34: кг | G34: =+Инвойс!G34 -> 3042 | H34: =+Инвойс!H34 -> 2510 | I34: =+Инвойс!I34 -> 1.95 | J34: =+Инвойс!J34 -> 4894.5 | K34: 0 | L34: 0 | M34: =+Инвойс!M34 -> 4894.5
A35: ИТОГО: | E35: =SUM(E30:E34) -> 2589 | G35: =+Инвойс!G35 -> 22714 | H35: =+Инвойс!H35 -> 19090 | J35: =+Инвойс!J35 -> 25537.5 | M35: =+Инвойс!M35 -> 25537.5
A36: Сумма прописью: | E36: =Лист1!B3 -> Двадцать пять тысяч пятьсот тридцать семь долларов США, 50 центов.
A40: Продавец | D40: Вахабов Ж.А. | G40: Покупатель | L40: Тукаев Р.Р
A41: =+Инвойс!A5 -> LLC «Fresh Food Export NN»
G56: =+[1]Инвойс!G13 -> Грузополучатель: | L56: Исаков И.Н.
G57: =+[1]Инвойс!G14 -> OOO «Сармант-ЮГ»

Sheet Лист2
A1: Код там. Поста 10412160 Оренбургская таможня т/п Соль-Илецкий, адрес 461504 г.Соль-Илецк, ул. Украинская, д.2
A2: DAP - г. Оренбург, Российская Федерация (согласно Incoterms 2010)
A5: Московская областная таможня Новомосковский Т/П (код поста 10132180) 142770 Москва, поселение Сосенское, дер. Николо-Хованское, СТР. 2004 СВХ ООО «ФУД ЛОГИСТИКС»
A6: DAP - г. Соль-Илецк, Российская Федерация (согласно Incoterms 2010)
A9: Челябинский таможенный пост г.Челябинск, ул.Игуменка 7 А, (код поста 10504080)
A10: DAP - г. Челябинск, Российская Федерация (согласно Incoterms 2010)
A13: 10309200, Т/П ПРИКУБАНСКИЙ, Г.КРАСНОДАР СВХ ООО "КОНСАЛТТАМОЖСЕРВИС" 350072, РФ, Г.КРАСНОДАР, УЛ.ТОПОЛИНАЯ, 4 Свидетельство СВХ № 10309/070721/10150/3
A14: DAP - г. Краснодар, Российская Федерация (согласно Incoterms 2010)
A17: г.Новосибирск, ч/з Новосибирский з/т пост, г.Новосибирск, ул.Толмачевская, д.1/1. код поста 10609030 | M17: Новосибирский р. посёлок
A18: DAP - г. Новосибирск, Российская Федерация (согласно Incoterms 2010) | M18: Крупской "Азия-Сибирь"
N20: код поста 10609030, т/п Новосибирский западный СВХ ООО "Азия-Сибирь" 630052 РФ. г. Новосибирск
A21: СВХ ООО "ОМАС" (код поста 10610050) 644117, Омская обл., г. Омск, ул. 3-я Молодежная, № лицензии: 10610/150515/10055/2
A22: DAP - г.Омск. Российская Федерация (согласно Incoterms 2010)
A25: т/п "Астраханский" Код поста 10311020, 414042, г. Астрахань, Трусовский р-н. ул. Мосина, д. 1Аlic. 10013/200111/10112/12 dđ 09/02/2021
A26: DAP - г. Астрахань, Российская Федерация (согласно Incoterms 2010)
A29: т/п Тольяттинский код поста 10412110 4450043 Самарская обл. г.Тольятти Автозаводский р-н. ул. Вокзальная д.2 СВХ «ГРИНЛАЙН»
A30: DAP - г.Тольятти, Российская Федерация (согласно Incoterms 2010)
A32: Октябрский таможенный пост, код поста 10502090, АО СИАЙТИ ТЕРМИНАЛ 620025, Свердловкая обл. г.Екатеринбург, ул.Бахчиванджи, д.2. Российская Федерация.
A33: DAP - г. Екатеринбург, Российская Федерация (согласно Incoterms 2010)
A35: Красноярский таможенный пост. Код поста 10606060. Адрес поста Российская Федерация г.Красноярск, ул.Ястынская 47в, строение 12. СВХ «Агротерминал-Таможня»
A36: DAP - г. Красноярск, Российская Федерация (согласно Incoterms 2010)

Sheet Лист1
A1: В ячейке Е2 должна быть ссылка на исходное число
E2: =Инвойс!M35 -> 25537.5 | G2: 357.79119
A3: Заглавная без НДС | B3: =SUBSTITUTE(B5,F9,F10,1) -> Двадцать пять тысяч пятьсот тридцать семь долларов США, 50 центов. | M3: Сегодня с утра судя по всему было | N3: =TODAY() -> 45897 | P3: =DAY(N3) -> 28 | Q3: =IF(Q4>7,S3,S4) -> августа | R3: =YEAR(N3) -> 2025 | S3: =IF(Q4=8,"августа",IF(Q4=9,"сентября",IF(Q4=10,"октября",IF(Q4=11,"ноября",IF(Q4=12,"декабря","не отсюда"))))) -> августа
A4: Заглавная с НДС | B4: =SUBSTITUTE(B6,F9,F10,1) -> Двадцать пять тысяч пятьсот тридцать семь долларов США, 50 центов. (в т.ч. НДС - 357,79) | K4: =CONCATENATE(" « ",P3," » ",Q3," ",R3," г.") -> « 28 » августа 2025 г. | Q4: =MONTH(N3) -> 8 | S4: =IF(Q4=1,"января",IF(Q4=2,"февраля",IF(Q4=3,"марта",IF(Q4=4,"апреля",IF(Q4=5,"мая",IF(Q4=6,"июня",IF(Q4=7,"июля","брать не отсюда"))))))) -> брать не отсюда
A5: маленькая без НДС | B5: =CONCATENATE(A8,A9,A10,A11,A12) -> двадцать пять тысяч пятьсот тридцать семь долларов США, 50 центов.
A6: маленькая с НДС | B6: =CONCATENATE(A8,A9,A10,A11,A12,B8,B9,C9) -> двадцать пять тысяч пятьсот тридцать семь долларов США, 50 центов. (в т.ч. НДС - 357,79)
H7: Для справки - смотрите примечания к ячейкам E4 B8 B9 этого листа и H2 и C34 предыдущего.
A8: =CONCATENATE(IF(B15=0,"",E15),IF(B16=0,"",IF(C17<20,IF(C17<16,IF(C17<10,E16,D17),F17),E16)),IF(B17=0,"",IF(NOT(B16=1),E17,"")),F18) | B8: (в т.ч. НДС - | F8: =CODE(B6) -> 228
A9: =CONCATENATE(IF(B19=0,"",E19),IF(B20=0,"",IF(C21<20,IF(C21<16,IF(C21<10,E20,D21),F21),E20)),IF(B21=0,"",IF(NOT(B20=1),E21,"")),F22) | B9: =ROUND((G2),2) -> 357.79 | C9: ) | F9: =CHAR(F8) -> д
A10: =CONCATENATE(IF(B23=0,"",E23),IF(B24=0,"",IF(C25<20,IF(C25<16,IF(C25<10,E24,D25),F25),E24)),IF(B25=0,"",IF(NOT(B24=1),E25,"")),F26) -> двадцать пять тысяч | F10: =PROPER(F9) -> Д
A11: =CONCATENATE(IF(B27=0,"",E27),IF(B28=0,"",IF(C29<20,IF(C29<16,IF(C29<10,E28,D29),F29),E28)),IF(B29=0,"",IF(NOT(B28=1),E29,"")),F30) -> пятьсот тридцать семь долларов США,
A12: =CONCATENATE(IF(C31=0,"0",C31),IF(C32=0,"0",C32)," ",F33) -> 50 центов. | M12: =TODAY() -> 45897
E13: =TRUNC(E2) -> 25537 | F13: рублей
A14: =TRUNC(A15/10) -> 0
A15: =TRUNC(A16/10) -> 0 | B15: =TRUNC(RIGHT(A15)) -> 0 | C15: =B15 -> 0 | E15: =IF(B15=1,E43,IF(B15=2,G35,IF(B15=3,G36,IF(B15=4,G37,IF(B15=5,G38,IF(B15=6,G39,IF(B15=7,G40,IF(B15=8,G41,G42)))))))) -> девятьсот
A16: =TRUNC(A17/10) -> 0 | B16: =TRUNC(RIGHT(A16)) -> 0 | C16: =IF(B16=1,"",B16) -> 0 | E16: =IF(OR(C16=0,B16=1),"",IF(B16=2,E35,IF(B16=3,E36,IF(B16=4,E37,IF(B16=5,E38,IF(B16=6,E39,IF(B16=7,E40,IF(B16=8,E41,E42))))))))
A17: =TRUNC(A19/10) -> 0 | B17: =TRUNC(RIGHT(A17)) -> 0 | C17: =IF(B16=1,B17+10,IF(B17=0,0,B17)) -> 0 | D17: =IF(AND(C17>9,C17<16),IF(C17=10,D34,IF(C17=11,D35,IF(C17=12,D36,IF(C17=13,D37,IF(C17=14,D38,IF(C17=15,D39,)))))),"") | E17: =IF(B17=1,A34,IF(B17=2,A35,IF(B17=3,A36,IF(B17=4,A37,IF(B17=5,A38,IF(B17=6,A39,IF(B17=7,A40,IF(B17=8,A41,A42)))))))) -> девять | F17: =IF(AND(C17>15,C17<20),IF(C17=16,D40,IF(C17=17,D41,IF(C17=18,D42,IF(C17=19,D43,)))),"")
E18: =B17+B16*10+B15*100 -> 0 | F18: =IF(E18=0,"",IF(B16=1,"миллиардов ",IF(B17=1,"милиард ",IF(OR(B17=2,B17=3,B17=4),"миллиарда ","милиардов "))))
A19: =TRUNC(A20/10) -> 0 | B19: =TRUNC(RIGHT(A19)) -> 0 | C19: =B19 -> 0 | E19: =IF(B19=1,E43,IF(B19=2,G35,IF(B19=3,G36,IF(B19=4,G37,IF(B19=5,G38,IF(B19=6,G39,IF(B19=7,G40,IF(B19=8,G41,G42)))))))) -> девятьсот
A20: =TRUNC(A21/10) -> 0 | B20: =TRUNC(RIGHT(A20)) -> 0 | C20: =IF(B20=1,"",B20) -> 0 | E20: =IF(OR(C20=0,B20=1),"",IF(B20=2,E35,IF(B20=3,E36,IF(B20=4,E37,IF(B20=5,E38,IF(B20=6,E39,IF(B20=7,E40,IF(B20=8,E41,E42))))))))
A21: =TRUNC(A23/10) -> 0 | B21: =TRUNC(RIGHT(A21)) -> 0 | C21: =IF(B20=1,B21+10,IF(B21=0,0,B21)) -> 0 | D21: =IF(AND(C21>9,C21<16),IF(C21=10,D34,IF(C21=11,D35,IF(C21=12,D36,IF(C21=13,D37,IF(C21=14,D38,IF(C21=15,D39,)))))),"") | E21: =IF(B21=1,A34,IF(B21=2,A35,IF(B21=3,A36,IF(B21=4,A37,IF(B21=5,A38,IF(B21=6,A39,IF(B21=7,A40,IF(B21=8,A41,A42)))))))) -> девять | F21: =IF(AND(C21>15,C21<20),IF(C21=16,D40,IF(C21=17,D41,IF(C21=18,D42,IF(C21=19,D43,)))),"")
E22: =B21+B20*10+B19*100 -> 0 | F22: =IF(E22=0,"",IF(B20=1,"миллионов ",IF(B21=1,"миллион ",IF(OR(B21=2,B21=3,B21=4),"миллиона ","миллионов "))))
A23: =TRUNC(A24/10) -> 0 | B23: =TRUNC(RIGHT(A23)) -> 0 | C23: =B23 -> 0 | E23: =IF(B23=1,E43,IF(B23=2,G35,IF(B23=3,G36,IF(B23=4,G37,IF(B23=5,G38,IF(B23=6,G39,IF(B23=7,G40,IF(B23=8,G41,G42)))))))) -> девятьсот
A24: =TRUNC(A25/10) -> 2 | B24: =TRUNC(RIGHT(A24)) -> 2 | C24: =IF(B24=1,"",B24) -> 2 | E24: =IF(OR(C24=0,B24=1),"",IF(B24=2,E35,IF(B24=3,E36,IF(B24=4,E37,IF(B24=5,E38,IF(B24=6,E39,IF(B24=7,E40,IF(B24=8,E41,E42)))))))) -> двадцать
A25: =TRUNC(A27/10) -> 25 | B25: =TRUNC(RIGHT(A25)) -> 5 | C25: =IF(B24=1,B25+10,IF(B25=0,0,B25)) -> 5 | D25: =IF(AND(C25>9,C25<16),IF(C25=10,D34,IF(C25=11,D35,IF(C25=12,D36,IF(C25=13,D37,IF(C25=14,D38,IF(C25=15,D39,)))))),"") | E25: =IF(B25=1,B34,IF(B25=2,B35,IF(B25=3,A36,IF(B25=4,A37,IF(B25=5,A38,IF(B25=6,A39,IF(B25=7,A40,IF(B25=8,A41,A42)))))))) -> пять | F25: =IF(AND(C25>15,C25<20),IF(C25=16,D40,IF(C25=17,D41,IF(C25=18,D42,IF(C25=19,D43,)))),"")
E26: =B23*100+B24*10+B25 -> 25 | F26: =IF(E26=0,"",IF(B24=1,"тысяч ",IF(B25=1,"тысяча ",IF(OR(B25=2,B25=3,B25=4),"тысячи ","тысяч ")))) -> тысяч
A27: =TRUNC(A28/10) -> 255 | B27: =TRUNC(RIGHT(A27)) -> 5 | C27: =B27 -> 5 | E27: =IF(B27=1,E43,IF(B27=2,G35,IF(B27=3,G36,IF(B27=4,G37,IF(B27=5,G38,IF(B27=6,G39,IF(B27=7,G40,IF(B27=8,G41,G42)))))))) -> пятьсот
A28: =TRUNC(A29/10) -> 2553 | B28: =TRUNC(RIGHT(A28)) -> 3 | C28: =IF(B28=1,"",B28) -> 3 | E28: =IF(OR(C28=0,B28=1),"",IF(C28=2,E35,IF(C28=3,E36,IF(C28=4,E37,IF(C28=5,E38,IF(C28=6,E39,IF(C28=7,E40,IF(C28=8,E41,E42)))))))) -> тридцать
A29: =E13 -> 25537 | B29: =TRUNC(RIGHT(A29)) -> 7 | C29: =IF(B28=1,B29+10,IF(B29=0,0,B29)) -> 7 | D29: =IF(AND(C29>9,C29<16),IF(C29=10,D34,IF(C29=11,D35,IF(C29=12,D36,IF(C29=13,D37,IF(C29=14,D38,IF(C29=15,D39,)))))),"") | E29: =IF(B29=1,A34,IF(B29=2,A35,IF(B29=3,A36,IF(B29=4,A37,IF(B29=5,A38,IF(B29=6,A39,IF(B29=7,A40,IF(B29=8,A41,A42)))))))) -> семь | F29: =IF(AND(C29>15,C29<20),IF(C29=16,D40,IF(C29=17,D41,IF(C29=18,D42,IF(C29=19,D43,)))),"")
E30: =B27*100+B28*10+B29 -> 537 | F30: =IF(E30+E26+E22+E18=0,"ноль долларов США,",IF(C29=1,"доллар США,",IF(OR(C29=2,C29=3,C29=4),"доллара США,","долларов США, "))) -> долларов США,
A31: =ROUND(100*(E2-E13),0) -> 50 | C31: =TRUNC(A31/10) -> 5 | E31: =IF(OR(C31=1,C31=0),"",IF(C31=2,E35,IF(C31=3,E36,IF(C31=4,E37,IF(C31=5,E38,IF(C31=6,E39,IF(C31=7,E40,IF(C31=8,E41,E42)))))))) -> пятьдесят
C32: =TRUNC(A31-C31*10) -> 0 | E32: =IF(C32=1,B34,IF(C32=2,B35,IF(C32=3,A36,IF(C32=4,A37,IF(C32=5,A38,IF(C32=6,A39,IF(C32=7,A40,IF(C32=8,A41,A42)))))))) -> девять
F33: центов.
A34: один | B34: одна | D34: десять
A35: два | B35: две | D35: одиннадцать | E35: двадцать | G35: двести
A36: три | D36: двенадцать | E36: тридцать | G36: триста
A37: четыре | D37: тринадцать | E37: сорок | G37: четыреста
A38: пять | D38: четырнадцать | E38: пятьдесят | G38: пятьсот
A39: шесть | D39: пятнадцать | E39: шестьдесят | G39: шестьсот
A40: семь | D40: шестнадцать | E40: семьдесят | G40: семьсот
...
