Workbook

Sheet Инвойс
C1: ИНВОЙС № BMX-O-10 от | F1: 24.08.2025г.
C2: к контракту № BMR-2025 от 16.08.2025 года
A4: Продавец: | G4: Покупатель:
A5: OOO “BMB МAX” | G5: ООО ТД «РЕСУРС»
A6: Республика Узбекистан. Ташкентская область, | G6: 125362, Город Москва, вн.тер.г. муниципальный округ
A7: Бекабадский район, МФЙ Найман, улица Мусаффо, дом 107 | G7: Южное Тушино, ул Свободы, д. 35, стр. 43, помещ. 92/3
A8: в “Узсаноаткурилиш” Банк операционный МФО 00440 | G8: Банк: Азия-Инвест Банк (АО) ИНН: 9705116064 КПП: 770501001
A9: Х/Р: 20208000005606798001 / Х/Р: 20208840605606798003 | G9: Р/Счет: 40702840100000019384 ; БИК: 044525234
A10: Х/Р: 20208840605606798003 | G10: Корр.счет: 30101810445250000234
A11: ИНН: 309774620 | G11: (SWIFT code: ASIJRUMM)
A13: Грузоотправитель: | G13: Грузополучатель:
A14: OOO “BMB МAX” | G14: OOO «Западные ворота»
A15: Республика Узбекистан. Ташкентская область, | G15: 108811, г. Москва, вн.тер.г. муниципальный округ
A16: Бекабадский район, МФЙ Найман, улица Мусаффо, дом 107 | G16: Солнцево, Киевское шоссе, 23-й км, д.8, стр.1
... A20: ИНН: 309774620 | G20: ИНН/КПП 5004025693/775101001 ОГРН 1135004001802
A22: Координаты | C22: ГЛОНАСС 41.3805768, 69.3187795
A23: Место там.очиски: | C23: СВХ АО "СИАЙТИ ТЕРМИНАЛ" 10502090 - т/п Октябрьский 620025, Свердловская обл., г. Екатеринбург, ул. Бахчиванджи, д. 2
A24: Условия поставки: | C24: DAP - с Амандык, Республика Казахстан
A25: Страна происхождения товара: | C25: Республика Узбекистан
A26: Вид транспорта и номер : | C26: Автотранспорт № | E26: 30444ABA/300811BA
A27: Урожай 2025 года
A28: № | B28: Наименование товаров (работ, услуг) | C28: Код ТН ВЭД | D28: Вид Упак | E28: мест | F28: Ед. изм. | G28: Кол-во товара | I28: Цена за ед. изм | J28: Стоимость поставки | K28: НДС | M28: Стоимость поставки с учетом НДС (доллар США)
G29: брутто | H29: нетто | J29: (нетто) тн. | K29: ставка | L29: сумма
A30: 1 | B30: Дыни свежие | C30: 0807190001 | D30: Карт.Коробок | E30: 1000 | F30: кг | G30: 23000 | H30: 21200 | I30: 0.2 | J30: =H30*I30 -> 4240 | K30: 0 | L30: 0 | M30: =J30 -> 4240
A31: ИТОГО: | E31: =SUM(E30:E30) -> 1000 | G31: =SUM(G30:G30) -> 23000 | H31: =SUM(H30:H30) -> 21200 | J31: =SUM(J30:J30) -> 4240 | M31: =SUM(M30:M30) -> 4240
A32: Сумма прописью: | E32: =Лист1!B3 -> Четыре тысячи двести сорок долларов США, 00 центов.
A34: Примечание: Товар уложен на деревянные палеты с дерев.рейками, которые не являются товаром и предназначенны для устойчивости и циркуляции охлаждающего воздуха. Вес паллет и дер.реек: 400 кг.
A36: Руководитель Поставщика_________________ | D36: Номуротов Ш.В
A38: М.П.
A40: Товар отпустил

Sheet CMR
B2: =+Инвойс!A5 -> OOO “BMB МAX”
B3: =+Инвойс!A6 -> Республика Узбекистан. Ташкентская область,
B4: =+Инвойс!A7 -> Бекабадский район, МФЙ Найман, улица Мусаффо, дом 107
B7: =+Инвойс!G14 -> OOO «Западные ворота»
B8: =+Инвойс!G15 -> 108811, г. Москва, вн.тер.г. муниципальный округ
B9: =+Инвойс!G16 -> Солнцево, Киевское шоссе, 23-й км, д.8, стр.1
B10: по поручению | C10: =+Инвойс!G5 -> ООО ТД «РЕСУРС»
B13: г.Оренбург/г.Казань/г.Москва/г.Санкт-Петербург/г.Пермь/г. Новосибирск /г.Красноярск/г.Челябинск/г.Екатеринбург/
A14: Российская Федерация | B14: /г. Владивосток/ г.Чита / г. Пенза / г. Краснодар / г.Пятигорск / г.Воронеж / /г.Нижневартовск/г.Нижний Новгород/г.Киров
B16: г.Уфа / /г. Иркутск /г.Омск /г. Ижевск/ г.Крым Симферополь/ Российская федерация
B18: Узбекистан Сыр. обл.
C22: =+Инвойс!F1 -> 24.08.2025г.
B24: =+CONCATENATE(Инвойс!C1,Инвойс!F1) -> ИНВОЙС № BMX-O-10 от 24.08.2025г.
B25: ТИР № XK87039375
B30: =+Инвойс!A30 -> 1 | C30: =+Инвойс!E30 -> 1000 | D30: =+Инвойс!D30 -> Карт.Коробок | F30: =+Инвойс!B30 -> Дыни свежие | G30: =+Инвойс!C30 -> 0807190001 | I30: =+Инвойс!G30 -> 23000
B45: =Инвойс!C23 -> СВХ АО "СИАЙТИ ТЕРМИНАЛ" 10502090 - т/п Октябрьский 620025, Свердловская обл., г. Екатеринбург, ул. Бахчиванджи, д. 2
B49: Сыр. обл | D49: =+C22 -> 24.08.2025г.
A57: а/м-п/п гос № | C57: =+Инвойс!E26 -> 30444ABA/300811BA

Sheet TIR
B2: Узбекистан
D7: Узбекистан | G7: Россия
B14: =+Инвойс!E26 -> 30444ABA/300811BA | H14: CMR № б/н от | J14: =+Инвойс!F1 -> 24.08.2025г.
G15: ИНВ № T-44 от 12.06.2018г. | H15: =+CMR!B24 -> ИНВОЙС № BMX-O-10 от 24.08.2025г.
F18: =+Инвойс!E30 -> 1000 | G18: =+CMR!F30 -> Дыни свежие
F19: =+Инвойс!D30 -> Карт.Коробок | G19: =+Инвойс!C30 -> 0807190001 | I19: Брутто | J19: =+Инвойс!G30 -> 23000
D47: =+F18+F20+F22+F24+F26+F28+F30+F32+F34+F36+F38+F40+F42 -> 1000
B48: РОССИЯ

Sheet SPETS
B1: СПЕЦИФИКАЦИЯ № BMX-O-10 от | F1: =+Инвойс!F1 -> 24.08.2025г.
C2: =+Инвойс!C2 -> к контракту № BMR-2025 от 16.08.2025 года
A4: Продавец: | G4: Покупатель:
A5: =+Инвойс!A5 -> OOO “BMB МAX” | G5: =+Инвойс!G5 -> ООО ТД «РЕСУРС»
A6: =+Инвойс!A6 -> Республика Узбекистан. Ташкентская область, | G6: =+Инвойс!G6 -> 125362, Город Москва, вн.тер.г. муниципальный округ
A7: =+Инвойс!A7 -> Бекабадский район, МФЙ Найман, улица Мусаффо, дом 107 | G7: =+Инвойс!G7 -> Южное Тушино, ул Свободы, д. 35, стр. 43, помещ. 92/3
A8: =+Инвойс!A8 -> в “Узсаноаткурилиш” Банк операционный МФО 00440 | G8: =+Инвойс!G8 -> Банк: Азия-Инвест Банк (АО) ИНН: 9705116064 КПП: 770501001
A9: =+Инвойс!A9 -> Х/Р: 20208000005606798001 / Х/Р: 20208840605606798003 | G9: =+Инвойс!G9 -> Р/Счет: 40702840100000019384 ; БИК: 044525234
A10: =+Инвойс!A10 -> Х/Р: 20208840605606798003 | G10: =+Инвойс!G10 -> Корр.счет: 30101810445250000234
A11: =+Инвойс!A11 -> ИНН: 309774620 | G11: =+Инвойс!G11 -> (SWIFT code: ASIJRUMM)
A13: Грузоотправитель: | G13: Грузополучатель:
A14: =+Инвойс!A14 -> OOO “BMB МAX” | G14: =+Инвойс!G14 -> OOO «Западные ворота»
A15: =+Инвойс!A15 -> Республика Узбекистан. Ташкентская область, | G15: =+Инвойс!G15 -> 108811, г. Москва, вн.тер.г. муниципальный округ
A16: =+Инвойс!A16 -> Бекабадский район, МФЙ Найман, улица Мусаффо, дом 107 | G16: =+Инвойс!G16 -> Солнцево, Киевское шоссе, 23-й км, д.8, стр.1
A17: =+Инвойс!A17 -> в “Узсаноаткурилиш” Банк операционный МФО 00440 | G17: =+Инвойс!G17 -> р/с USD 40702810501400013450
A18: =+Инвойс!A18 -> Х/Р: 20208000005606798001 / Х/Р: 20208840605606798003 | G18: =+Инвойс!G18 -> Банк: Филиал АО «АЛЬФА-БАНК»
A19: =+Инвойс!A19 -> Х/Р: 20208840605606798003 | G19: =+Инвойс!G19 -> к/с: 30101810200000000593
A20: =+Инвойс!A20 -> ИНН: 309774620 | G20: =+Инвойс!G20 -> ИНН/КПП 5004025693/775101001 ОГРН 1135004001802
A22: Дополнительная информация
A23: Место там.очиски: | C23: СВХ ООО "Мультимодальные Транспортные Системы" 10013230 - т/п Михневский 142840, Московская обл., Ступинский р-н, р.п. Михнево, ул. Старомихневская, уч. 47, влд. 47
A24: Условия поставки: | C24: =+Инвойс!C24 -> DAP - с Амандык, Республика Казахстан
A25: Страна происхождения товара: | C25: Республика Узбекистан
A26: Вид транспорта и номер : | C26: Автотранспорт № | E26: =+Инвойс!E26 -> 30444ABA/300811BA
A27: Условия оплаты: не позднее 180 дней с даты поставки (даты выпуска товара на территории РФ)
A28: № | B28: Наименование товаров (работ, услуг) | C28: Код ТН ВЭД | D28: Вид Упак | E28: мест | F28: Ед. изм. | G28: Кол-во товара | I28: Цена за ед. изм | J28: Стоимость поставки | K28: НДС | M28: Стоимость поставки с учетом НДС (доллар США)
G29: брутто | H29: нетто | J29: (нетто) тн. | K29: ставка | L29: сумма
A30: =+Инвойс!A30 -> 1 | B30: =+Инвойс!B30 -> Дыни свежие | C30: =+Инвойс!C30 -> 0807190001 | D30: =+Инвойс!D30 -> Карт.Коробок | E30: =+Инвойс!E30 -> 1000 | F30: =+Инвойс!F30 -> кг | G30: =+Инвойс!G30 -> 23000 | H30: =+Инвойс!H30 -> 21200 | ... J30: =+Инвойс!J30 -> 4240 | K30: 0 | L30: 0 | M30: =+Инвойс!M30 -> 4240
A31: ИТОГО: | E31: =SUM(E30:E30) -> 1000 | G31: =SUM(G30:G30) -> 23000 | H31: =SUM(H30:H30) -> 21200 | J31: =SUM(J30:J30) -> 4240 | M31: =SUM(M30:M30) -> 4240
A32: Сумма прописью: | E32: =Лист1!B3 -> Четыре тысячи двести сорок долларов США, 00 центов.
A36: Директор: ООО «BMB МАХ» | D36: =+Инвойс!D36 -> Номуротов Ш.В | G36: Директор: | H36: =Инвойс!G5 -> ООО ТД «РЕСУРС» | K36: Касимов Д. Д.

Sheet Лист2
A1: СВХ ООО "Агротерминал-Таможня" 10606060 - т/п Красноярский 660131, Красноярский край, г. Красноярск, ул. Ястынская, д. 47, стр. 12
D2: DAP - с Казыгурт , Республика Казахстан | I2: MAYSKIY
A3: СВХ ООО "Мультимодальные Транспортные Системы" 10132130 - т/п Михневский 142840, Московская обл., Ступинский р-н, р.п. Михнево, ул. Старомихневская, уч. 47, влд. 47
D4: DAP - с Амандык, Республика Казахстан | I4: ILICH
A5: СВХ ООО "Легион Сибирь Плюс" 10609030 - т/п Новосибирский западный 630052, Новосибирская обл., г. Новосибирск, ул. Толмачевская, д. 1/1
D6: DAP - с Жибек Жолы , Республика Казахстан | I6: YALLAMA
A7: СВХ ООО "Уралкомплект" 10412130 - т/п Оренбургский 460027, Оренбургская обл., г. Оренбург, ул. Донгузская, д. 62А
D8: DAP - с Акжигит , Республика Казахстан | I8: DOUT-OTA
A9: СВХ ОАО ГК "Армада" 10311020 - т/п Астраханский 414042, Астраханская обл., г. Астрахань, ул. Мосина, д. 1А
A11: СВХ ООО "Южно-Уральская Внешнеэкономическая Компания" 10504080 - т/п Челябинский 454108, Челябинская обл., г. Челябинск, ул. Игуменка, д. 7А
A13: СВХ ООО "ГРИНЛАЙН" 10412110 - т/п Тольяттинский 445043, Самарская обл., г. Тольятти, ул. Вокзальная, д. 2
A15: СВХ АО "СИАЙТИ ТЕРМИНАЛ" 10502090 - т/п Октябрьский 620025, Свердловская обл., г. Екатеринбург, ул. Бахчиванджи, д. 2
A17: СВХ ООО "КонсалтТаможСервис" 10309200 - т/п Прикубанский 350072, Краснодарский край, г. Краснодар, ул. Тополиная, д. 4
A19: СВХ ООО "ОМАС" 10610050 - т/п Омский 644117, Омская обл., г. Омск, ул. 3-я Молодежная, д. 6

Sheet Лист1
A1: В ячейке Е2 должна быть ссылка на исходное число
E2: =Инвойс!M31 -> 4240 | G2: 357.79119
A3: Заглавная без НДС | B3: =SUBSTITUTE(B5,F9,F10,1) -> Четыре тысячи двести сорок долларов США, 00 центов. | M3: Сегодня с утра судя по всему было | N3: =TODAY() -> 45896 | P3: =DAY(N3) -> 27 | Q3: =IF(Q4>7,S3,S4) -> августа | R3: =YEAR(N3) -> 2025 | S3: =IF(Q4=8,"августа",IF(Q4=9,"сентября",IF(Q4=10,"октября",IF(Q4=11,"ноября",IF(Q4=12,"декабря","не отсюда"))))) -> августа
A4: Заглавная с НДС | B4: =SUBSTITUTE(B6,F9,F10,1) -> Четыре тысячи двести сорок долларов США, 00 центов. (в т.ч. НДС - 357,79) | K4: =CONCATENATE(" « ",P3," » ",Q3," ",R3," г.") -> « 27 » августа 2025 г. | Q4: =MONTH(N3) -> 8 | S4: =IF(Q4=1,"января",IF(Q4=2,"февраля",IF(Q4=3,"марта",IF(Q4=4,"апреля",IF(Q4=5,"мая",IF(Q4=6,"июня",IF(Q4=7,"июля","брать не отсюда"))))))) -> брать не отсюда
A5: маленькая без НДС | B5: =CONCATENATE(A8,A9,A10,A11,A12) -> четыре тысячи двести сорок долларов США, 00 центов.
A6: маленькая с НДС | B6: =CONCATENATE(A8,A9,A10,A11,A12,B8,B9,C9) -> четыре тысячи двести сорок долларов США, 00 центов. (в т.ч. НДС - 357,79)
H7: Для справки - смотрите примечания к ячейкам E4 B8 B9 этого листа и H2 и C34 предыдущего.
A8: =CONCATENATE(IF(B15=0,"",E15),IF(B16=0,"",IF(C17<20,IF(C17<16,IF(C17<10,E16,D17),F17),E16)),IF(B17=0,"",IF(NOT(B16=1),E17,"")),F18) | B8: (в т.ч. НДС - | F8: =CODE(B6) -> 247
A9: =CONCATENATE(IF(B19=0,"",E19),IF(B20=0,"",IF(C21<20,IF(C21<16,IF(C21<10,E20,D21),F21),E20)),IF(B21=0,"",IF(NOT(B20=1),E21,"")),F22) | B9: =ROUND((G2),2) -> 357.79 | C9: ) | F9: =CHAR(F8) -> ч
A10: =CONCATENATE(IF(B23=0,"",E23),IF(B24=0,"",IF(C25<20,IF(C25<16,IF(C25<10,E24,D25),F25),E24)),IF(B25=0,"",IF(NOT(B24=1),E25,"")),F26) -> четыре тысячи | F10: =PROPER(F9) -> Ч
A11: =CONCATENATE(IF(B27=0,"",E27),IF(B28=0,"",IF(C29<20,IF(C29<16,IF(C29<10,E28,D29),F29),E28)),IF(B29=0,"",IF(NOT(B28=1),E29,"")),F30) -> двести сорок долларов США,
A12: =CONCATENATE(IF(C31=0,"0",C31),IF(C32=0,"0",C32)," ",F33) -> 00 центов. | M12: =TODAY() -> 45896
E13: =TRUNC(E2) -> 4240 | F13: рублей
A14: =TRUNC(A15/10) -> 0
A15: =TRUNC(A16/10) -> 0 | B15: =TRUNC(RIGHT(A15)) -> 0 | C15: =B15 -> 0 | E15: =IF(B15=1,E43,IF(B15=2,G35,IF(B15=3,G36,IF(B15=4,G37,IF(B15=5,G38,IF(B15=6,G39,IF(B15=7,G40,IF(B15=8,G41,G42)))))))) -> девятьсот
A16: =TRUNC(A17/10) -> 0 | B16: =TRUNC(RIGHT(A16)) -> 0 | C16: =IF(B16=1,"",B16) -> 0 | E16: =IF(OR(C16=0,B16=1),"",IF(B16=2,E35,IF(B16=3,E36,IF(B16=4,E37,IF(B16=5,E38,IF(B16=6,E39,IF(B16=7,E40,IF(B16=8,E41,E42))))))))
A17: =TRUNC(A19/10) -> 0 | B17: =TRUNC(RIGHT(A17)) -> 0 | C17: =IF(B16=1,B17+10,IF(B17=0,0,B17)) -> 0 | D17: =IF(AND(C17>9,C17<16),IF(C17=10,D34,IF(C17=11,D35,IF(C17=12,D36,IF(C17=13,D37,IF(C17=14,D38,IF(C17=15,D39,)))))),"") | E17: =IF(B17=1,A34,IF(B17=2,A35,IF(B17=3,A36,IF(B17=4,A37,IF(B17=5,A38,IF(B17=6,A39,IF(B17=7,A40,IF(B17=8,A41,A42)))))))) -> девять | F17: =IF(AND(C17>15,C17<20),IF(C17=16,D40,IF(C17=17,D41,IF(C17=18,D42,IF(C17=19,D43,)))),"")
E18: =B17+B16*10+B15*100 -> 0 | F18: =IF(E18=0,"",IF(B16=1,"миллиардов ",IF(B17=1,"милиард ",IF(OR(B17=2,B17=3,B17=4),"миллиарда ","милиардов "))))
A19: =TRUNC(A20/10) -> 0 | B19: =TRUNC(RIGHT(A19)) -> 0 | C19: =B19 -> 0 | E19: =IF(B19=1,E43,IF(B19=2,G35,IF(B19=3,G36,IF(B19=4,G37,IF(B19=5,G38,IF(B19=6,G39,IF(B19=7,G40,IF(B19=8,G41,G42)))))))) -> девятьсот
A20: =TRUNC(A21/10) -> 0 | B20: =TRUNC(RIGHT(A20)) -> 0 | C20: =IF(B20=1,"",B20) -> 0 | E20: =IF(OR(C20=0,B20=1),"",IF(B20=2,E35,IF(B20=3,E36,IF(B20=4,E37,IF(B20=5,E38,IF(B20=6,E39,IF(B20=7,E40,IF(B20=8,E41,E42))))))))
A21: =TRUNC(A23/10) -> 0 | B21: =TRUNC(RIGHT(A21)) -> 0 | C21: =IF(B20=1,B21+10,IF(B21=0,0,B21)) -> 0 | D21: =IF(AND(C21>9,C21<16),IF(C21=10,D34,IF(C21=11,D35,IF(C21=12,D36,IF(C21=13,D37,IF(C21=14,D38,IF(C21=15,D39,)))))),"") | E21: =IF(B21=1,A34,IF(B21=2,A35,IF(B21=3,A36,IF(B21=4,A37,IF(B21=5,A38,IF(B21=6,A39,IF(B21=7,A40,IF(B21=8,A41,A42)))))))) -> девять | F21: =IF(AND(C21>15,C21<20),IF(C21=16,D40,IF(C21=17,D41,IF(C21=18,D42,IF(C21=19,D43,)))),"")
E22: =B21+B20*10+B19*100 -> 0 | F22: =IF(E22=0,"",IF(B20=1,"миллионов ",IF(B21=1,"миллион ",IF(OR(B21=2,B21=3,B21=4),"миллиона ","миллионов "))))
A23: =TRUNC(A24/10) -> 0 | B23: =TRUNC(RIGHT(A23)) -> 0 | C23: =B23 -> 0 | E23: =IF(B23=1,E43,IF(B23=2,G35,IF(B23=3,G36,IF(B23=4,G37,IF(B23=5,G38,IF(B23=6,G39,IF(B23=7,G40,IF(B23=8,G41,G42)))))))) -> девятьсот
A24: =TRUNC(A25/10) -> 0 | B24: =TRUNC(RIGHT(A24)) -> 0 | C24: =IF(B24=1,"",B24) -> 0 | E24: =IF(OR(C24=0,B24=1),"",IF(B24=2,E35,IF(B24=3,E36,IF(B24=4,E37,IF(B24=5,E38,IF(B24=6,E39,IF(B24=7,E40,IF(B24=8,E41,E42))))))))
A25: =TRUNC(A27/10) -> 4 | B25: =TRUNC(RIGHT(A25)) -> 4 | C25: =IF(B24=1,B25+10,IF(B25=0,0,B25)) -> 4 | D25: =IF(AND(C25>9,C25<16),IF(C25=10,D34,IF(C25=11,D35,IF(C25=12,D36,IF(C25=13,D37,IF(C25=14,D38,IF(C25=15,D39,)))))),"") | E25: =IF(B25=1,B34,IF(B25=2,B35,IF(B25=3,A36,IF(B25=4,A37,IF(B25=5,A38,IF(B25=6,A39,IF(B25=7,A40,IF(B25=8,A41,A42)))))))) -> четыре | F25: =IF(AND(C25>15,C25<20),IF(C25=16,D40,IF(C25=17,D41,IF(C25=18,D42,IF(C25=19,D43,)))),"")
E26: =B23*100+B24*10+B25 -> 4 | F26: =IF(E26=0,"",IF(B24=1,"тысяч ",IF(B25=1,"тысяча ",IF(OR(B25=2,B25=3,B25=4),"тысячи ","тысяч ")))) -> тысячи
A27: =TRUNC(A28/10) -> 42 | B27: =TRUNC(RIGHT(A27)) -> 2 | C27: =B27 -> 2 | E27: =IF(B27=1,E43,IF(B27=2,G35,IF(B27=3,G36,IF(B27=4,G37,IF(B27=5,G38,IF(B27=6,G39,IF(B27=7,G40,IF(B27=8,G41,G42)))))))) -> двести
A28: =TRUNC(A29/10) -> 424 | B28: =TRUNC(RIGHT(A28)) -> 4 | C28: =IF(B28=1,"",B28) -> 4 | E28: =IF(OR(C28=0,B28=1),"",IF(C28=2,E35,IF(C28=3,E36,IF(C28=4,E37,IF(C28=5,E38,IF(C28=6,E39,IF(C28=7,E40,IF(C28=8,E41,E42)))))))) -> сорок
A29: =E13 -> 4240 | B29: =TRUNC(RIGHT(A29)) -> 0 | C29: =IF(B28=1,B29+10,IF(B29=0,0,B29)) -> 0 | D29: =IF(AND(C29>9,C29<16),IF(C29=10,D34,IF(C29=11,D35,IF(C29=12,D36,IF(C29=13,D37,IF(C29=14,D38,IF(C29=15,D39,)))))),"") | E29: =IF(B29=1,A34,IF(B29=2,A35,IF(B29=3,A36,IF(B29=4,A37,IF(B29=5,A38,IF(B29=6,A39,IF(B29=7,A40,IF(B29=8,A41,A42)))))))) -> девять | F29: =IF(AND(C29>15,C29<20),IF(C29=16,D40,IF(C29=17,D41,IF(C29=18,D42,IF(C29=19,D43,)))),"")
E30: =B27*100+B28*10+B29 -> 240 | F30: =IF(E30+E26+E22+E18=0,"ноль долларов США,",IF(C29=1,"доллар США,",IF(OR(C29=2,C29=3,C29=4),"доллара США,","долларов США, "))) -> долларов США,
A31: =ROUND(100*(E2-E13),0) -> 0 | C31: =TRUNC(A31/10) -> 0 | E31: =IF(OR(C31=1,C31=0),"",IF(C31=2,E35,IF(C31=3,E36,IF(C31=4,E37,IF(C31=5,E38,IF(C31=6,E39,IF(C31=7,E40,IF(C31=8,E41,E42))))))))
C32: =TRUNC(A31-C31*10) -> 0 | E32: =IF(C32=1,B34,IF(C32=2,B35,IF(C32=3,A36,IF(C32=4,A37,IF(C32=5,A38,IF(C32=6,A39,IF(C32=7,A40,IF(C32=8,A41,A42)))))))) -> девять
F33: центов.
A34: один | B34: одна | D34: десять
A35: два | B35: две | D35: одиннадцать | E35: двадцать | G35: двести
A36: три | D36: двенадцать | E36: тридцать | G36: триста
A37: четыре | D37: тринадцать | E37: сорок | G37: четыреста
A38: пять | D38: четырнадцать | E38: пятьдесят | G38: пятьсот
A39: шесть | D39: пятнадцать | E39: шестьдесят | G39: шестьсот
A40: семь | D40: шестнадцать | E40: семьдесят | G40: семьсот
...
